{
 "cells": [
  {
   "cell_type": "code",
   "execution_count": 1,
   "id": "09707999",
   "metadata": {},
   "outputs": [],
   "source": [
    "import numpy as np\n",
    "from keras.models import Sequential\n",
    "from keras.layers import AveragePooling2D"
   ]
  },
  {
   "cell_type": "code",
   "execution_count": 2,
   "id": "b075045c",
   "metadata": {},
   "outputs": [],
   "source": [
    "# define input image\n",
    "image = np.array([[2, 2, 7, 3],\n",
    "                  [9, 4, 6, 1],\n",
    "                  [8, 5, 2, 4],\n",
    "                  [3, 1, 2, 6]])\n",
    "image = image.reshape(1, 4, 4, 1)"
   ]
  },
  {
   "cell_type": "code",
   "execution_count": 3,
   "id": "4cb839a3",
   "metadata": {},
   "outputs": [],
   "source": [
    "# define model containing just a single average pooling layer\n",
    "model = Sequential(\n",
    "    [AveragePooling2D(pool_size = 2, strides = 2)])"
   ]
  },
  {
   "cell_type": "code",
   "execution_count": 4,
   "id": "d77af6a8",
   "metadata": {},
   "outputs": [
    {
     "ename": "TypeError",
     "evalue": "in user code:\n\n    File \"C:\\Users\\LENOVO\\anaconda3\\lib\\site-packages\\keras\\engine\\training.py\", line 2041, in predict_function  *\n        return step_function(self, iterator)\n    File \"C:\\Users\\LENOVO\\anaconda3\\lib\\site-packages\\keras\\engine\\training.py\", line 2027, in step_function  **\n        outputs = model.distribute_strategy.run(run_step, args=(data,))\n    File \"C:\\Users\\LENOVO\\anaconda3\\lib\\site-packages\\keras\\engine\\training.py\", line 2015, in run_step  **\n        outputs = model.predict_step(data)\n    File \"C:\\Users\\LENOVO\\anaconda3\\lib\\site-packages\\keras\\engine\\training.py\", line 1983, in predict_step\n        return self(x, training=False)\n    File \"C:\\Users\\LENOVO\\anaconda3\\lib\\site-packages\\keras\\utils\\traceback_utils.py\", line 70, in error_handler\n        raise e.with_traceback(filtered_tb) from None\n\n    TypeError: Exception encountered when calling layer \"average_pooling2d\" \"                 f\"(type AveragePooling2D).\n    \n    Value passed to parameter 'value' has DataType int32 not in list of allowed values: float16, bfloat16, float32, float64\n    \n    Call arguments received by layer \"average_pooling2d\" \"                 f\"(type AveragePooling2D):\n      • inputs=tf.Tensor(shape=(None, 4, 4, 1), dtype=int32)\n",
     "output_type": "error",
     "traceback": [
      "\u001b[1;31m---------------------------------------------------------------------------\u001b[0m",
      "\u001b[1;31mTypeError\u001b[0m                                 Traceback (most recent call last)",
      "Input \u001b[1;32mIn [4]\u001b[0m, in \u001b[0;36m<cell line: 2>\u001b[1;34m()\u001b[0m\n\u001b[0;32m      1\u001b[0m \u001b[38;5;66;03m# generate pooled output\u001b[39;00m\n\u001b[1;32m----> 2\u001b[0m output \u001b[38;5;241m=\u001b[39m \u001b[43mmodel\u001b[49m\u001b[38;5;241;43m.\u001b[39;49m\u001b[43mpredict\u001b[49m\u001b[43m(\u001b[49m\u001b[43mimage\u001b[49m\u001b[43m)\u001b[49m\n",
      "File \u001b[1;32m~\\anaconda3\\lib\\site-packages\\keras\\utils\\traceback_utils.py:70\u001b[0m, in \u001b[0;36mfilter_traceback.<locals>.error_handler\u001b[1;34m(*args, **kwargs)\u001b[0m\n\u001b[0;32m     67\u001b[0m     filtered_tb \u001b[38;5;241m=\u001b[39m _process_traceback_frames(e\u001b[38;5;241m.\u001b[39m__traceback__)\n\u001b[0;32m     68\u001b[0m     \u001b[38;5;66;03m# To get the full stack trace, call:\u001b[39;00m\n\u001b[0;32m     69\u001b[0m     \u001b[38;5;66;03m# `tf.debugging.disable_traceback_filtering()`\u001b[39;00m\n\u001b[1;32m---> 70\u001b[0m     \u001b[38;5;28;01mraise\u001b[39;00m e\u001b[38;5;241m.\u001b[39mwith_traceback(filtered_tb) \u001b[38;5;28;01mfrom\u001b[39;00m \u001b[38;5;28mNone\u001b[39m\n\u001b[0;32m     71\u001b[0m \u001b[38;5;28;01mfinally\u001b[39;00m:\n\u001b[0;32m     72\u001b[0m     \u001b[38;5;28;01mdel\u001b[39;00m filtered_tb\n",
      "File \u001b[1;32m~\\AppData\\Local\\Temp\\__autograph_generated_file_ksbaxq6.py:15\u001b[0m, in \u001b[0;36mouter_factory.<locals>.inner_factory.<locals>.tf__predict_function\u001b[1;34m(iterator)\u001b[0m\n\u001b[0;32m     13\u001b[0m \u001b[38;5;28;01mtry\u001b[39;00m:\n\u001b[0;32m     14\u001b[0m     do_return \u001b[38;5;241m=\u001b[39m \u001b[38;5;28;01mTrue\u001b[39;00m\n\u001b[1;32m---> 15\u001b[0m     retval_ \u001b[38;5;241m=\u001b[39m ag__\u001b[38;5;241m.\u001b[39mconverted_call(ag__\u001b[38;5;241m.\u001b[39mld(step_function), (ag__\u001b[38;5;241m.\u001b[39mld(\u001b[38;5;28mself\u001b[39m), ag__\u001b[38;5;241m.\u001b[39mld(iterator)), \u001b[38;5;28;01mNone\u001b[39;00m, fscope)\n\u001b[0;32m     16\u001b[0m \u001b[38;5;28;01mexcept\u001b[39;00m:\n\u001b[0;32m     17\u001b[0m     do_return \u001b[38;5;241m=\u001b[39m \u001b[38;5;28;01mFalse\u001b[39;00m\n",
      "\u001b[1;31mTypeError\u001b[0m: in user code:\n\n    File \"C:\\Users\\LENOVO\\anaconda3\\lib\\site-packages\\keras\\engine\\training.py\", line 2041, in predict_function  *\n        return step_function(self, iterator)\n    File \"C:\\Users\\LENOVO\\anaconda3\\lib\\site-packages\\keras\\engine\\training.py\", line 2027, in step_function  **\n        outputs = model.distribute_strategy.run(run_step, args=(data,))\n    File \"C:\\Users\\LENOVO\\anaconda3\\lib\\site-packages\\keras\\engine\\training.py\", line 2015, in run_step  **\n        outputs = model.predict_step(data)\n    File \"C:\\Users\\LENOVO\\anaconda3\\lib\\site-packages\\keras\\engine\\training.py\", line 1983, in predict_step\n        return self(x, training=False)\n    File \"C:\\Users\\LENOVO\\anaconda3\\lib\\site-packages\\keras\\utils\\traceback_utils.py\", line 70, in error_handler\n        raise e.with_traceback(filtered_tb) from None\n\n    TypeError: Exception encountered when calling layer \"average_pooling2d\" \"                 f\"(type AveragePooling2D).\n    \n    Value passed to parameter 'value' has DataType int32 not in list of allowed values: float16, bfloat16, float32, float64\n    \n    Call arguments received by layer \"average_pooling2d\" \"                 f\"(type AveragePooling2D):\n      • inputs=tf.Tensor(shape=(None, 4, 4, 1), dtype=int32)\n"
     ]
    }
   ],
   "source": [
    "# generate pooled output\n",
    "output = model.predict(image)"
   ]
  },
  {
   "cell_type": "code",
   "execution_count": null,
   "id": "666f6d90",
   "metadata": {},
   "outputs": [],
   "source": [
    " # print output image\n",
    "output = np.squeeze(output)\n",
    "print(output)"
   ]
  },
  {
   "cell_type": "code",
   "execution_count": null,
   "id": "9326c2ec",
   "metadata": {},
   "outputs": [],
   "source": []
  }
 ],
 "metadata": {
  "kernelspec": {
   "display_name": "Python 3 (ipykernel)",
   "language": "python",
   "name": "python3"
  },
  "language_info": {
   "codemirror_mode": {
    "name": "ipython",
    "version": 3
   },
   "file_extension": ".py",
   "mimetype": "text/x-python",
   "name": "python",
   "nbconvert_exporter": "python",
   "pygments_lexer": "ipython3",
   "version": "3.9.12"
  }
 },
 "nbformat": 4,
 "nbformat_minor": 5
}
